Workbook

Sheet Coded
A1: MultiValues | B1: Griglia Italiano | C1: Griglia Inglês | D1: Resp.1 | E1: Resp.2
A2: TT(4X2) | B2: Tipo Trazione | C2: Traction type | D2: FWD | E2: FWD
A3: TT(4X4) | B3: Tipo Trazione | C3: Traction type | D3: 4WD | E3: 4WD
A4: ELT(BSG12) | B4: TIPO ELETTRIFICAZIONE | C4: TIPO ELETTRIFICAZIONE | D4: MICROHEV BSG 12V | E4: MICROHEV BSG 12V
A5: ELT(NO) | B5: TIPO ELETTRIFICAZIONE | C5: TIPO ELETTRIFICAZIONE | D5: ICE | E5: ICE
A6: VERS(*) | B6: SINCOM | C6: SINCOM | D6: (*) | E6: (*)
A7: KW(125) | B7: Potenza max KW | C7: Maximum power kW | D7: 127 | E7: 127
A8: KW(99) | B8: Potenza max KW | C8: Maximum power kW | D8: 96 | E8: 96
A9: TC(PKDC) | B9: Numero Porte | C9: Number of doors | D9: 4 | E9: 4
A10: TC(PKUP) | B10: Numero Porte | C10: Number of doors | D10: 2 | E10: 2
A11: VLE(6) | B11: Numero Cilindri | C11: Number of valves per cylinder | D11: 6 | E11: 6
A12: VLE(8) | B12: Numero Cilindri | C12: Number of valves per cylinder | D12: 8 | E12: 8
A13: NC(3) | B13: Numero Cilindri | C13: Number of cylinders | D13: 3 | E13: 3
A14: NC(4) | B14: Numero Cilindri | C14: Number of cylinders | D14: 4
A15: NP(2) | B15: Num Valvole per Cilindro | C15: Number of valves per cylinder | D15: 2
A16: NP(4) | B16: Num Valvole per Cilindro | C16: Number of valves per cylinder | D16: 4
A17: AM(38 | B17: Mercati | C17: Markets | D17: ARGENTINA | E17: ARGENTINA
A18: AM(38) | B18: Mercati | C18: Markets | D18: ARGENTINA | E18: ARGENTINA
A19: AM(11 | B19: Mercati | C19: Markets | D19: BRASILE,BRAZIL | E19: BRASILE,BRAZIL
A20: AM(11) | B20: Mercati | C20: Markets | D20: BRASILE,BRAZIL | E20: BRASILE,BRAZIL
A21: AM(47 | B21: Mercati | C21: Markets | D21: MESSICO,MEXICO | E21: MESSICO,MEXICO
A22: AM(47) | B22: Mercati | C22: Markets | D22: MESSICO,MEXICO | E22: MESSICO,MEXICO
A23: AM(55 | B23: Mercati | C23: Markets | D23: ALTRI MERCATI,OTHER MARKETS | E23: ALTRI MERCATI,OTHER MARKETS
A24: AM(55) | B24: Mercati | C24: Markets | D24: ALTRI MERCATI,OTHER MARKETS | E24: ALTRI MERCATI,OTHER MARKETS
A25: M(00) | B25: Marchio | C25: Brand | D25: FIAT | E25: FIAT
A26: M(58) | B26: Marchio | C26: Brand | D26: RAM | E26: RAM
A27: M(74) | B27: Marchio | C27: Brand | D27: PEUGEOT | E27: PEUGEOT
A28: MARCA(74) | B28: Marchio | C28: Brand | D28: PEUGEOT | E28: PEUGEOT
... A73: PC(CA72) | B73: Famiglia Cambio | C73: Gear Family | D73: AT6 | E73: Aut. Aisin
A74: CC(1.6) | B74: Cilindrata (l) | C74: Engine displacement (liters) | D74: 1.6 | E74: 1.6
A75: CC(2.4) | B75: Cilindrata (l) | C75: Engine displacement (liters) | D75: 2.4 | E75: 2.4
A76: CC(1.0) | B76: Cilindrata (l) | C76: Engine displacement (liters) | D76: 1 | E76: 1
A77: CC(1.3 | B77: Cilindrata (l) | C77: Engine displacement (liters) | D77: 1.3 | E77: 1.3
A78: CC(1.3) | B78: Cilindrata (l) | C78: Engine displacement (liters) | D78: 1.3 | E78: 1.3
A79: CC(1.4) | B79: Cilindrata (l) | C79: Engine displacement (liters) | D79: 1.4 | E79: 1.4
A80: CC(1.8 | B80: Cilindrata (l) | C80: Engine displacement (liters) | D80: 1.8 | E80: 1.8
A81: CC(1.8) | B81: Cilindrata (l) | C81: Engine displacement (liters) | D81: 1.8 | E81: 1.8
A82: CC(2.0) | B82: Cilindrata (l) | C82: Engine displacement (liters) | D82: 2 | E82: 2
A83: CC(2.2) | B83: Cilindrata (l) | C83: Engine displacement (liters) | D83: 2.2 | E83: 2.2
A84: CMB(ALC) | B84: Carburante | C84: Fuel | D84: Alcool | E84: Alcool
...

Sheet Updated
O1: multivalues | Q1: Italiano | R1: Inglês | S1: Model | T1: Resp.1 | U1: Resp.2
A2: =TRANSPOSE(_xlfn._xlws.FILTER(Coded!A:A,Coded!B:B=Updated!Q2)) -> TT(4X2) | B2: TT(4X4) | Q2: Tipo Trazione | R2: Traction type | S2: 2261 | T2: FWD
A3: =TRANSPOSE(_xlfn._xlws.FILTER(Coded!A:A,Coded!B:B=Updated!Q3)) -> TT(4X2) | B3: TT(4X4) | Q3: Tipo Trazione | R3: Traction type | S3: 2261 | T3: 4WD
A4: =TRANSPOSE(_xlfn._xlws.FILTER(Coded!A:A,Coded!B:B=Updated!Q4)) -> TT(4X2) | B4: TT(4X4) | Q4: Tipo Trazione | R4: Traction type | S4: 2651 | T4: Ant
A5: =TRANSPOSE(_xlfn._xlws.FILTER(Coded!A:A,Coded!B:B=Updated!Q5)) -> TT(4X2) | B5: TT(4X4) | Q5: Tipo Trazione | R5: Traction type | S5: 5211 | U5: FWD
A6: =TRANSPOSE(_xlfn._xlws.FILTER(Coded!A:A,Coded!B:B=Updated!Q6)) -> TT(4X2) | B6: TT(4X4) | Q6: Tipo Trazione | R6: Traction type | S6: 5211 | U6: 4WD
A7: =TRANSPOSE(_xlfn._xlws.FILTER(Coded!A:A,Coded!B:B=Updated!Q7)) -> TT(4X2) | B7: TT(4X4) | Q7: Tipo Trazione | R7: Traction type | S7: 5511 | U7: AWD
A8: =TRANSPOSE(_xlfn._xlws.FILTER(Coded!A:A,Coded!B:B=Updated!Q8)) -> ELT(BSG12) | B8: ELT(NO) | Q8: TIPO ELETTRIFICAZIONE | R8: - | S8: 3630 | T8: BSG12
A9: =TRANSPOSE(_xlfn._xlws.FILTER(Coded!A:A,Coded!B:B=Updated!Q9)) -> KW(125) | B9: KW(99) | Q9: Potenza max KW | R9: Maximum power kW | S9: 2261 | T9: 0
A10: =TRANSPOSE(_xlfn._xlws.FILTER(Coded!A:A,Coded!B:B=Updated!Q10)) -> KW(125) | B10: KW(99) | Q10: Potenza max KW | R10: Maximum power kW | S10: 3410 | T10: 57
A11: =TRANSPOSE(_xlfn._xlws.FILTER(Coded!A:A,Coded!B:B=Updated!Q11)) -> KW(125) | B11: KW(99) | Q11: Potenza max KW | R11: Maximum power kW | S11: 3630 | T11: 136
A12: =TRANSPOSE(_xlfn._xlws.FILTER(Coded!A:A,Coded!B:B=Updated!Q12)) -> KW(125) | B12: KW(99) | Q12: Potenza max KW | R12: Maximum power kW | S12: 3630 | T12: 127
A13: =TRANSPOSE(_xlfn._xlws.FILTER(Coded!A:A,Coded!B:B=Updated!Q13)) -> KW(125) | B13: KW(99) | Q13: Potenza max KW | R13: Maximum power kW | S13: 3630 | T13: 80
A14: =TRANSPOSE(_xlfn._xlws.FILTER(Coded!A:A,Coded!B:B=Updated!Q14)) -> KW(125) | B14: KW(99) | Q14: Potenza max KW | R14: Maximum power kW | S14: 3630 | T14: 92
A15: =TRANSPOSE(_xlfn._xlws.FILTER(Coded!A:A,Coded!B:B=Updated!Q15)) -> KW(125) | B15: KW(99) | Q15: Potenza max KW | R15: Maximum power kW | S15: 3630 | T15: 70
A16: =TRANSPOSE(_xlfn._xlws.FILTER(Coded!A:A,Coded!B:B=Updated!Q16)) -> KW(125) | B16: KW(99) | Q16: Potenza max KW | R16: Maximum power kW | S16: 3630 | T16: 84
A17: =TRANSPOSE(_xlfn._xlws.FILTER(Coded!A:A,Coded!B:B=Updated!Q17)) -> KW(125) | B17: KW(99) | Q17: Potenza max KW | R17: Maximum power kW | S17: 3760 | T17: 131
A18: =TRANSPOSE(_xlfn._xlws.FILTER(Coded!A:A,Coded!B:B=Updated!Q18)) -> KW(125) | B18: KW(99) | Q18: Potenza max KW | R18: Maximum power kW | S18: 5211 | U18: 129
A19: =TRANSPOSE(_xlfn._xlws.FILTER(Coded!A:A,Coded!B:B=Updated!Q19)) -> KW(125) | B19: KW(99) | Q19: Potenza max KW | R19: Maximum power kW | S19: 5211 | U19: 127
A20: =TRANSPOSE(_xlfn._xlws.FILTER(Coded!A:A,Coded!B:B=Updated!Q20)) -> KW(125) | B20: KW(99) | Q20: Potenza max KW | R20: Maximum power kW | S20: 5511 | U20: 000
A21: =TRANSPOSE(_xlfn._xlws.FILTER(Coded!A:A,Coded!B:B=Updated!Q21)) -> KW(125) | B21: KW(99) | Q21: Potenza max KW | R21: Maximum power kW | S21: 5980 | U21: 200
A22: =TRANSPOSE(_xlfn._xlws.FILTER(Coded!A:A,Coded!B:B=Updated!Q22)) -> KW(125) | B22: KW(99) | Q22: Potenza max KW | R22: Maximum power kW | S22: 5980 | U22: 147
A23: =TRANSPOSE(_xlfn._xlws.FILTER(Coded!A:A,Coded!B:B=Updated!Q23)) -> TC(PKDC) | B23: TC(PKUP) | Q23: Numero Porte | R23: Number of doors | S23: 5211 | U23: 4
A24: =TRANSPOSE(_xlfn._xlws.FILTER(Coded!A:A,Coded!B:B=Updated!Q24)) -> TC(PKDC) | B24: TC(PKUP) | Q24: Numero Porte | R24: Number of doors | S24: 5511 | U24: 5
A25: =TRANSPOSE(_xlfn._xlws.FILTER(Coded!A:A,Coded!B:B=Updated!Q25)) -> VLE(6) | B25: VLE(8) | C25: NC(3) | D25: NC(4) | Q25: Numero Cilindri | R25: Number of valves per cylinder | S25: 2651 | T25: 4
A26: =TRANSPOSE(_xlfn._xlws.FILTER(Coded!A:A,Coded!B:B=Updated!Q26)) -> VLE(6) | B26: VLE(8) | C26: NC(3) | D26: NC(4) | Q26: Numero Cilindri | R26: Number of valves per cylinder | S26: 2810 | T26: 3
A27: =TRANSPOSE(_xlfn._xlws.FILTER(Coded!A:A,Coded!B:B=Updated!Q27)) -> VLE(6) | B27: VLE(8) | C27: NC(3) | D27: NC(4) | Q27: Numero Cilindri | R27: Number of valves per cylinder | S27: 5211 | U27: 4
A28: =TRANSPOSE(_xlfn._xlws.FILTER(Coded!A:A,Coded!B:B=Updated!Q28)) -> VLE(6) | B28: VLE(8) | C28: NC(3) | D28: NC(4) | Q28: Numero Cilindri | R28: Number of cylinders | S28: 2651 | T28: 4
A29: =TRANSPOSE(_xlfn._xlws.FILTER(Coded!A:A,Coded!B:B=Updated!Q29)) -> VLE(6) | B29: VLE(8) | C29: NC(3) | D29: NC(4) | Q29: Numero Cilindri | R29: Number of cylinders | S29: 2810 | T29: 3
A30: =TRANSPOSE(_xlfn._xlws.FILTER(Coded!A:A,Coded!B:B=Updated!Q30)) -> VLE(6) | B30: VLE(8) | C30: NC(3) | D30: NC(4) | Q30: Numero Cilindri | R30: Number of cylinders | S30: 5211 | U30: 4
A31: =TRANSPOSE(_xlfn._xlws.FILTER(Coded!A:A,Coded!B:B=Updated!Q31)) -> NP(2) | B31: NP(4) | Q31: Num Valvole per Cilindro | R31: Number of valves per cylinder | S31: 5211 | U31: 4
A32: =TRANSPOSE(_xlfn._xlws.FILTER(Coded!A:A,Coded!B:B=Updated!Q32)) -> ECO(BPL8) | B32: ECO(E6C) | C32: BPL7) | D32: BPL7P) | E32: ECO(BPL6 | F32: ECO(BPL7 | G32: ECO(E6C) | H32: ECO(CF6) | I32: ECO(BPL6) | J32: ECO(BPL7) | K32: ECO(BPL7P) | L32: ECO(PL7O) | M32: ECO(PL7P) | N32: ECO(PL8) | Q32: Livello Ecologia | R32: Ecology level | S32: 2261 | T32: Proconve L8 + ORVR
A33: =TRANSPOSE(_xlfn._xlws.FILTER(Coded!A:A,Coded!B:B=Updated!Q33)) -> ECO(BPL8) | B33: ECO(E6C) | C33: BPL7) | D33: BPL7P) | E33: ECO(BPL6 | F33: ECO(BPL7 | G33: ECO(E6C) | H33: ECO(CF6) | I33: ECO(BPL6) | J33: ECO(BPL7) | K33: ECO(BPL7P) | L33: ECO(PL7O) | M33: ECO(PL7P) | N33: ECO(PL8) | Q33: Livello Ecologia | R33: Ecology level | S33: 2261 | T33: EURO 5
A34: =TRANSPOSE(_xlfn._xlws.FILTER(Coded!A:A,Coded!B:B=Updated!Q34)) -> ECO(BPL8) | B34: ECO(E6C) | C34: BPL7) | D34: BPL7P) | E34: ECO(BPL6 | F34: ECO(BPL7 | G34: ECO(E6C) | H34: ECO(CF6) | I34: ECO(BPL6) | J34: ECO(BPL7) | K34: ECO(BPL7P) | L34: ECO(PL7O) | M34: ECO(PL7P) | N34: ECO(PL8) | Q34: Livello Ecologia | R34: Ecology level | S34: 2261 | T34: CF6
A35: =TRANSPOSE(_xlfn._xlws.FILTER(Coded!A:A,Coded!B:B=Updated!Q35)) -> ECO(BPL8) | B35: ECO(E6C) | C35: BPL7) | D35: BPL7P) | E35: ECO(BPL6 | F35: ECO(BPL7 | G35: ECO(E6C) | H35: ECO(CF6) | I35: ECO(BPL6) | J35: ECO(BPL7) | K35: ECO(BPL7P) | L35: ECO(PL7O) | M35: ECO(PL7P) | N35: ECO(PL8) | Q35: Livello Ecologia | R35: Ecology level | S35: 2651 | T35: CEE-F5+EOBD
A36: =TRANSPOSE(_xlfn._xlws.FILTER(Coded!A:A,Coded!B:B=Updated!Q36)) -> ECO(BPL8) | B36: ECO(E6C) | C36: BPL7) | D36: BPL7P) | E36: ECO(BPL6 | F36: ECO(BPL7 | G36: ECO(E6C) | H36: ECO(CF6) | I36: ECO(BPL6) | J36: ECO(BPL7) | K36: ECO(BPL7P) | L36: ECO(PL7O) | M36: ECO(PL7P) | N36: ECO(PL8) | Q36: Livello Ecologia | R36: Ecology level | S36: 2810 | T36: E6C
A37: =TRANSPOSE(_xlfn._xlws.FILTER(Coded!A:A,Coded!B:B=Updated!Q37)) -> ECO(BPL8) | B37: ECO(E6C) | C37: BPL7) | D37: BPL7P) | E37: ECO(BPL6 | F37: ECO(BPL7 | G37: ECO(E6C) | H37: ECO(CF6) | I37: ECO(BPL6) | J37: ECO(BPL7) | K37: ECO(BPL7P) | L37: ECO(PL7O) | M37: ECO(PL7P) | N37: ECO(PL8) | Q37: Livello Ecologia | R37: Ecology level | S37: 3410 | T37: E5
A38: =TRANSPOSE(_xlfn._xlws.FILTER(Coded!A:A,Coded!B:B=Updated!Q38)) -> ECO(BPL8) | B38: ECO(E6C) | C38: BPL7) | D38: BPL7P) | E38: ECO(BPL6 | F38: ECO(BPL7 | G38: ECO(E6C) | H38: ECO(CF6) | I38: ECO(BPL6) | J38: ECO(BPL7) | K38: ECO(BPL7P) | L38: ECO(PL7O) | M38: ECO(PL7P) | N38: ECO(PL8) | Q38: Livello Ecologia | R38: Ecology level | S38: 3410 | T38: Proconve L8 + ORVR + PGM
A39: =TRANSPOSE(_xlfn._xlws.FILTER(Coded!A:A,Coded!B:B=Updated!Q39)) -> ECO(BPL8) | B39: ECO(E6C) | C39: BPL7) | D39: BPL7P) | E39: ECO(BPL6 | F39: ECO(BPL7 | G39: ECO(E6C) | H39: ECO(CF6) | I39: ECO(BPL6) | J39: ECO(BPL7) | K39: ECO(BPL7P) | L39: ECO(PL7O) | M39: ECO(PL7P) | N39: ECO(PL8) | Q39: Livello Ecologia | R39: Ecology level | S39: 3630 | T39: Proconve L8
A40: =TRANSPOSE(_xlfn._xlws.FILTER(Coded!A:A,Coded!B:B=Updated!Q40)) -> ECO(BPL8) | B40: ECO(E6C) | C40: BPL7) | D40: BPL7P) | E40: ECO(BPL6 | F40: ECO(BPL7 | G40: ECO(E6C) | H40: ECO(CF6) | I40: ECO(BPL6) | J40: ECO(BPL7) | K40: ECO(BPL7P) | L40: ECO(PL7O) | M40: ECO(PL7P) | N40: ECO(PL8) | Q40: Livello Ecologia | R40: Ecology level | S40: 3630 | T40: CEE-F6+EOBD
...

Sheet tb_de_para
A1: Multivalues | B1: Griglia Italiano | C1: Griglia Inglês | D1: Model | E1: Resp.1 | F1: Resp.2
A2: 0 | B2: Potenza max KW | C2: Maximum power kW | D2: 226 | E2: 0
A3: 1,3 | B3: Cilindrata (l) | C3: Engine displacement (liters) | D3: 226 | E3: 1,3
A4: 2,2 | B4: Cilindrata (l) | C4: Engine displacement (liters) | D4: 226 | E4: 2,2
A5: 4WD | B5: Tipo Trazione | C5: Traction type | D5: 226 | E5: 4WD
A6: 5 | B6: Numero Porte | C6: Number of doors | D6: 226 | E6: 5
A7: AT6 | B7: Famiglia Cambio | C7: Gear Family | D7: 226 | E7: AT6
A8: AT9 | B8: Famiglia Cambio | C8: Gear Family | D8: 226 | E8: AT9
A9: Benzina | B9: Carburante | C9: Fuel | D9: 226 | E9: Benzina
A10: CF6 | B10: Livello Ecologia | C10: Ecology level | D10: 226 | E10: CF6
A11: DIESEL | B11: Carburante | C11: Fuel | D11: 226 | E11: DIESEL
A12: EURO 5 | B12: Livello Ecologia | C12: Ecology level | D12: 226 | E12: EURO 5
A13: FIAT | B13: Marchio | C13: Brand | D13: 226 | E13: FIAT
... A210: liv. 5 | B210: Livello Allestimento | C210: Trim Level | D210: 376 | E210: liv. 5
A211: 1,3 | B211: Cilindrata (l) | C211: Engine displacement (liters) | D211: 521 | F211: 1,3
A212: 127 | B212: Potenza max KW | C212: Maximum power kW | D212: 521 | F212: 127
A213: 129 | B213: Potenza max KW | C213: Maximum power kW | D213: 521 | F213: 129
A214: 4 | B214: Numero Porte | C214: Number of doors | D214: 521 | F214: 4
A215: 4 | B215: Numero Cilindri | C215: Number of valves per cylinder | D215: 521 | F215: 4
A216: 4 | B216: Numero Cilindri | C216: Number of cylinders | D216: 521 | F216: 4
A217: 4 | B217: Num Valvole per Cilindro | C217: Number of valves per cylinder | D217: 521 | F217: 4
A218: 4WD | B218: Tipo Trazione | C218: Traction type | D218: 521 | F218: 4WD
A219: CEE-E6C | B219: Livello Ecologia | C219: Ecology level | D219: 521 | F219: CEE-E6C
A220: EURO 5 | B220: Livello Ecologia | C220: Ecology level | D220: 521 | F220: EURO 5
A221: FWD | B221: Tipo Trazione | C221: Traction type | D221: 521 | F221: FWD
A222: Flex | B222: Carburante | C222: Fuel | D222: 521 | F222: Flex
... A283: Turbo | B283: Caratteristiche Motore | C283: Engine Features | D283: 598 | F283: Turbo
